Workbook

Sheet 📊 MASTER
A1: 📊 MASTER — นิยายทั้งหมด
A2: ทั้งหมด 50 เรื่อง | กำลังลง: 8 | ผลิตแล้ว: 19 | กำลังผลิต: 13 | รอลง: 8 | ลงครบแล้ว: 1 | หยุดลง: 1
A4: # | B4: ชื่อเรื่อง | C4: แนว | D4: ตอนทั้งหมด | E4: สถานะ | F4: HIT | G4: ธัญวลัย | H4: readAwrite | I4: Dek-D | J4: Fictionlog | K4: หมายเหตุ
A5: 1 | B5: เมียลับท่านประธาน | C5: CEO | D5: 50 | E5: กำลังลง | F5: 🔥 | G5: 35 | H5: 30 | I5: 22 | J5: —
A6: 2 | B6: บังคับรักมาเฟียร้าย | C6: มาเฟีย | D6: 45 | E6: กำลังลง | F6: 🔥 | G6: 40 | H6: 35 | I6: — | J6: 28
A7: 3 | B7: พลาดท้องกับเจ้านาย | C7: ออฟฟิศ | D7: 40 | E7: กำลังลง | G7: 18 | H7: 14 | I7: — | J7: —
A8: 4 | B8: หมอร้ายได้อีก | C8: หมอ | D8: 50 | E8: กำลังลง | F8: 🔥 | G8: 42 | H8: 38 | I8: 30 | J8: 25
A9: 5 | B9: ฮาเร็มท่านCEO | C9: ฮาเร็ม | D9: 50 | E9: กำลังลง | F9: 🔥 | G9: 45 | H9: 40 | I9: 32 | J9: 28
A10: 6 | B10: คุณชายร้ายกาจ | C10: CEO | D10: 45 | E10: กำลังลง | G10: 20 | H10: — | I10: — | J10: —
A11: 7 | B11: จอมใจนายทหาร | C11: ทหาร | D11: 40 | E11: กำลังลง | G11: 15 | H11: — | I11: — | J11: —
A12: 8 | B12: กลับมารักฉันอีกครั้ง | C12: แก้แค้น | D12: 50 | E12: กำลังลง | G12: 12 | H12: — | I12: — | J12: —
A13: 9 | B13: ดักรักเลขาสาว | C13: CEO | D13: 40 | E13: ผลิตแล้ว | G13: รอลง | H13: รอลง | I13: รอลง | J13: —
A14: 10 | B14: คืนนั้นกับคนแปลกหน้า | C14: ดราม่า | D14: 45 | E14: ผลิตแล้ว | G14: รอลง | H14: รอลง | I14: — | J14: —
A15: 11 | B15: ซ่อนรักไว้ในใจ | C15: โรแมนซ์ | D15: 35 | E15: ผลิตแล้ว | G15: รอลง | H15: รอลง | I15: — | J15: —
A16: 12 | B16: สัญญารักร้อน | C16: สัญญา | D16: 40 | E16: กำลังผลิต | G16: รอลง | H16: — | I16: — | J16: —
A17: 13 | B17: เกมรักอันตราย | C17: สืบสวน | D17: 45 | E17: กำลังผลิต | G17: รอลง | H17: — | I17: — | J17: —
A18: 14 | B18: รักข้ามชนชั้น | C18: ดราม่า | D18: 40 | E18: ผลิตแล้ว | G18: รอลง | H18: รอลง | I18: — | J18: —
A19: 15 | B19: เสน่ห์ร้ายนายตำรวจ | C19: ตำรวจ | D19: 45 | E19: ผลิตแล้ว | G19: รอลง | H19: — | I19: — | J19: —
A20: 16 | B20: จับหัวใจเจ้าชายมาเฟีย | C20: มาเฟีย | D20: 50 | E20: กำลังผลิต | G20: รอลง | H20: — | I20: — | J20: —
A21: 17 | B21: รักนี้มีแต่เธอ | C21: โรแมนซ์ | D21: 35 | E21: รอลง | G21: รอลง | H21: — | I21: — | J21: —
A22: 18 | B22: พิษรักนางบำเรอ | C22: ย้อนยุค | D22: 40 | E22: ผลิตแล้ว | G22: รอลง | H22: รอลง | I22: — | J22: —
A23: 19 | B23: ลิขิตรักข้ามเวลา | C23: แฟนตาซี | D23: 45 | E23: กำลังผลิต | G23: รอลง | H23: — | I23: — | J23: —
A24: 20 | B24: เชลยรักทรราช | C24: ย้อนยุค | D24: 40 | E24: รอลง | G24: รอลง | H24: — | I24: — | J24: —
... A27: 23 | B27: ตกหลุมรักนายจอมหยิ่ง | C27: CEO | D27: 45 | E27: กำลังผลิต | G27: รอลง | H27: — | I27: — | J27: —
A28: 24 | B28: ทาสรักจอมโหด | C28: BDSM | D28: 35 | E28: ลงครบแล้ว | G28: 35 | H28: 35 | I28: — | J28: —
A29: 25 | B29: แม่บ้านตัวร้าย | C29: ดราม่า | D29: 40 | E29: หยุดลง | G29: 18 | H29: 14 | I29: — | J29: —
A30: 26 | B30: สะดุดรักยัยจอมแก่น | C30: โรแมนซ์ | D30: 40 | E30: ผลิตแล้ว | G30: รอลง | H30: — | I30: — | J30: —
A31: 27 | B31: เพลิงรักนักบินหนุ่ม | C31: โรแมนซ์ | D31: 35 | E31: ผลิตแล้ว | G31: รอลง | H31: — | I31: — | J31: —
A32: 28 | B32: รักพิษสวาท | C32: ดราม่า | D32: 45 | E32: กำลังผลิต | G32: รอลง | H32: — | I32: — | J32: —
A33: 29 | B33: หัวใจทศกัณฐ์ | C33: แฟนตาซี | D33: 50 | E33: กำลังผลิต | G33: รอลง | H33: — | I33: — | J33: —
A34: 30 | B34: ขังรักไว้ในอ้อมแขน | C34: มาเฟีย | D34: 40 | E34: รอลง | G34: รอลง | H34: — | I34: — | J34: —
A35: 31 | B35: ว่าที่เมียเจ้าพ่อ | C35: มาเฟีย | D35: 45 | E35: ผลิตแล้ว | G35: รอลง | H35: — | I35: — | J35: —
A36: 32 | B36: สลับชีวิตรัก | C36: แฟนตาซี | D36: 40 | E36: ผลิตแล้ว | G36: รอลง | H36: — | I36: — | J36: —
A37: 33 | B37: รักต้องห้ามนายหัว | C37: CEO | D37: 45 | E37: กำลังผลิต | G37: รอลง | H37: — | I37: — | J37: —
A38: 34 | B38: บาปรักลวงใจ | C38: ดราม่า | D38: 40 | E38: รอลง | G38: รอลง | H38: — | I38: — | J38: —
A39: 35 | B39: จับจองนางในฝัน | C39: โรแมนซ์ | D39: 35 | E39: ผลิตแล้ว | G39: รอลง | H39: — | I39: — | J39: —
A40: 36 | B40: เล่ห์รักวังวน | C40: ดราม่า | D40: 40 | E40: กำลังผลิต | G40: รอลง | H40: — | I40: — | J40: —
A41: 37 | B41: หมาป่าหัวใจสิงห์ | C41: แฟนตาซี | D41: 50 | E41: กำลังผลิต | G41: รอลง | H41: — | I41: — | J41: —
... A54: 50 | B54: รักสุดขอบฟ้า | C54: โรแมนซ์ | D54: 35 | E54: ผลิตแล้ว | G54: รอลง | H54: — | I54: — | J54: —

Sheet 📆 MONTHLY
A1: 📆 แผนเดือน กุมภาพันธ์ 2026
A2: เป้าหมาย: เปิดเรื่องใหม่ 3 เรื่อง/สัปดาห์ = 12 เรื่อง/เดือน
A4: เป้าเปิดใหม่ | B4: เปิดแล้ว | C4: เหลืออีก | D4: กำลังลงอยู่ | E4: HIT | F4: หยุดลง
A5: 12 | B5: 0 | C5: 12 | D5: 8 | E5: 4 | F5: 1
A6: เรื่อง | B6: เรื่อง | C6: เรื่อง | D6: เรื่อง | E6: เรื่อง | F6: เรื่อง
A8: 📅 แผนเปิดเรื่องใหม่รายสัปดาห์
A9: สัปดาห์ | B9: จันทร์ | C9: พุธ | D9: ศุกร์ | E9: สถานะ | F9: หมายเหตุ
A10: W1: 3-7 ก.พ. | B10: ดักรักเลขาสาว | C10: คืนนั้นกับคนแปลกหน้า | D10: ซ่อนรักไว้ในใจ | E10: 📍 สัปดาห์นี้
A11: W2: 10-14 ก.พ. | B11: รักข้ามชนชั้น | C11: เสน่ห์ร้ายนายตำรวจ | D11: รักนี้มีแต่เธอ | E11: รอดำเนินการ
A12: W3: 17-21 ก.พ. | B12: พิษรักนางบำเรอ | C12: เชลยรักทรราช | D12: บ่วงรักสาวใช้ | E12: รอดำเนินการ
A13: W4: 24-28 ก.พ. | B13: ร้อนรักวัยดรุณ | C13: สะดุดรักยัยจอมแก่น | D13: เพลิงรักนักบินหนุ่ม | E13: รอดำเนินการ
A16: 📊 สถานะนิยายทั้งหมด
A17: สถานะ | B17: จำนวน | C17: รายชื่อ
A18: กำลังลง | B18: 8 | C18: เมียลับท่านประธาน, บังคับรักมาเฟียร้าย, พลาดท้องกับเจ้านาย, หมอร้ายได้อีก, ฮาเร็มท่านCEO...
A19: ผลิตแล้ว | B19: 19 | C19: ดักรักเลขาสาว, คืนนั้นกับคนแปลกหน้า, ซ่อนรักไว้ในใจ, รักข้ามชนชั้น, เสน่ห์ร้ายนายตำรวจ...
A20: กำลังผลิต | B20: 13 | C20: สัญญารักร้อน, เกมรักอันตราย, จับหัวใจเจ้าชายมาเฟีย, ลิขิตรักข้ามเวลา, ตกหลุมรักนายจอมหยิ่ง...
A21: รอลง | B21: 8 | C21: รักนี้มีแต่เธอ, เชลยรักทรราช, บ่วงรักสาวใช้, ขังรักไว้ในอ้อมแขน, บาปรักลวงใจ...
A22: ลงครบแล้ว | B22: 1 | C22: ทาสรักจอมโหด
A23: หยุดลง | B23: 1 | C23: แม่บ้านตัวร้าย
A26: 📚 รายละเอียดนิยายที่ลงเดือนนี้ (ดึงจาก sheet แต่ละเรื่อง)
A27: # | B27: ชื่อเรื่อง | C27: แนว | D27: ตอนทั้งหมด | E27: สถานะ | F27: HIT | G27: ธัญวลัย ลงถึงตอน | H27: readAwrite ลงถึงตอน | I27: Dek-D ลงถึงตอน | J27: Fictionlog ลงถึงตอน | K27: หมายเหตุ
A28: 1 | B28: =เมียลับท่านประธาน!A1 -> 🔥 เมียลับท่านประธาน | C28: CEO | D28: 50 | E28: กำลังลง | F28: 🔥 | G28: =เมียลับท่านประธาน!B5 -> 35 | H28: =เมียลับท่านประธาน!B6 -> 30 | I28: =เมียลับท่านประธาน!B7 -> 22 | J28: =เมียลับท่านประธาน!B8 -> —
A29: 2 | B29: =บังคับรักมาเฟียร้าย!A1 -> 🔥 บังคับรักมาเฟียร้าย | C29: มาเฟีย | D29: 45 | E29: กำลังลง | F29: 🔥 | G29: =บังคับรักมาเฟียร้าย!B5 -> 40 | H29: =บังคับรักมาเฟียร้าย!B6 -> 35 | I29: =บังคับรักมาเฟียร้าย!B7 -> — | J29: =บังคับรักมาเฟียร้าย!B8 -> 28
A30: 3 | B30: =พลาดท้องกับเจ้านาย!A1 -> พลาดท้องกับเจ้านาย | C30: ออฟฟิศ | D30: 40 | E30: กำลังลง | G30: =พลาดท้องกับเจ้านาย!B5 -> 18 | H30: =พลาดท้องกับเจ้านาย!B6 -> 14 | I30: =พลาดท้องกับเจ้านาย!B7 -> — | J30: =พลาดท้องกับเจ้านาย!B8 -> —
A31: 4 | B31: =หมอร้ายได้อีก!A1 -> 🔥 หมอร้ายได้อีก | C31: หมอ | D31: 50 | E31: กำลังลง | F31: 🔥 | G31: =หมอร้ายได้อีก!B5 -> 42 | H31: =หมอร้ายได้อีก!B6 -> 38 | I31: =หมอร้ายได้อีก!B7 -> 30 | J31: =หมอร้ายได้อีก!B8 -> 25
A32: 5 | B32: =ฮาเร็มท่านCEO!A1 -> 🔥 ฮาเร็มท่านCEO | C32: ฮาเร็ม | D32: 50 | E32: กำลังลง | F32: 🔥 | G32: =ฮาเร็มท่านCEO!B5 -> 45 | H32: =ฮาเร็มท่านCEO!B6 -> 40 | I32: =ฮาเร็มท่านCEO!B7 -> 32 | J32: =ฮาเร็มท่านCEO!B8 -> 28
A33: 6 | B33: =คุณชายร้ายกาจ!A1 -> คุณชายร้ายกาจ | C33: CEO | D33: 45 | E33: กำลังลง | G33: =คุณชายร้ายกาจ!B5 -> 20 | H33: =คุณชายร้ายกาจ!B6 -> — | I33: =คุณชายร้ายกาจ!B7 -> — | J33: =คุณชายร้ายกาจ!B8 -> —
A34: 7 | B34: =จอมใจนายทหาร!A1 -> จอมใจนายทหาร | C34: ทหาร | D34: 40 | E34: กำลังลง | G34: =จอมใจนายทหาร!B5 -> 15 | H34: =จอมใจนายทหาร!B6 -> — | I34: =จอมใจนายทหาร!B7 -> — | J34: =จอมใจนายทหาร!B8 -> —
A35: 8 | B35: =กลับมารักฉันอีกครั้ง!A1 -> กลับมารักฉันอีกครั้ง | C35: แก้แค้น | D35: 50 | E35: กำลังลง | G35: =กลับมารักฉันอีกครั้ง!B5 -> 12 | H35: =กลับมารักฉันอีกครั้ง!B6 -> — | I35: =กลับมารักฉันอีกครั้ง!B7 -> — | J35: =กลับมารักฉันอีกครั้ง!B8 -> —
A36: 9 | B36: =ดักรักเลขาสาว!A1 -> ดักรักเลขาสาว | C36: CEO | D36: 40 | E36: ผลิตแล้ว | G36: =ดักรักเลขาสาว!B5 -> — | H36: =ดักรักเลขาสาว!B6 -> — | I36: =ดักรักเลขาสาว!B7 -> — | J36: =ดักรักเลขาสาว!B8 -> —
A37: 10 | B37: =คืนนั้นกับคนแปลกหน้า!A1 -> คืนนั้นกับคนแปลกหน้า | C37: ดราม่า | D37: 45 | E37: ผลิตแล้ว | G37: =คืนนั้นกับคนแปลกหน้า!B5 -> — | H37: =คืนนั้นกับคนแปลกหน้า!B6 -> — | I37: =คืนนั้นกับคนแปลกหน้า!B7 -> — | J37: =คืนนั้นกับคนแปลกหน้า!B8 -> —
A38: 11 | B38: =ซ่อนรักไว้ในใจ!A1 -> ซ่อนรักไว้ในใจ | C38: โรแมนซ์ | D38: 35 | E38: ผลิตแล้ว | G38: =ซ่อนรักไว้ในใจ!B5 -> — | H38: =ซ่อนรักไว้ในใจ!B6 -> — | I38: =ซ่อนรักไว้ในใจ!B7 -> — | J38: =ซ่อนรักไว้ในใจ!B8 -> —
A39: 12 | B39: =สัญญารักร้อน!A1 -> สัญญารักร้อน | C39: สัญญา | D39: 40 | E39: กำลังผลิต | G39: =สัญญารักร้อน!B5 -> — | H39: =สัญญารักร้อน!B6 -> — | I39: =สัญญารักร้อน!B7 -> — | J39: =สัญญารักร้อน!B8 -> —
A40: 13 | B40: =เกมรักอันตราย!A1 -> เกมรักอันตราย | C40: สืบสวน | D40: 45 | E40: กำลังผลิต | G40: =เกมรักอันตราย!B5 -> — | H40: =เกมรักอันตราย!B6 -> — | I40: =เกมรักอันตราย!B7 -> — | J40: =เกมรักอันตราย!B8 -> —
A41: 14 | B41: =รักข้ามชนชั้น!A1 -> รักข้ามชนชั้น | C41: ดราม่า | D41: 40 | E41: ผลิตแล้ว | G41: =รักข้ามชนชั้น!B5 -> — | H41: =รักข้ามชนชั้น!B6 -> — | I41: =รักข้ามชนชั้น!B7 -> — | J41: =รักข้ามชนชั้น!B8 -> —
A42: 15 | B42: =เสน่ห์ร้ายนายตำรวจ!A1 -> เสน่ห์ร้ายนายตำรวจ | C42: ตำรวจ | D42: 45 | E42: ผลิตแล้ว | G42: =เสน่ห์ร้ายนายตำรวจ!B5 -> — | H42: =เสน่ห์ร้ายนายตำรวจ!B6 -> — | I42: =เสน่ห์ร้ายนายตำรวจ!B7 -> — | J42: =เสน่ห์ร้ายนายตำรวจ!B8 -> —
A43: 16 | B43: =จับหัวใจเจ้าชายมาเฟี!A1 -> จับหัวใจเจ้าชายมาเฟีย | C43: มาเฟีย | D43: 50 | E43: กำลังผลิต | G43: =จับหัวใจเจ้าชายมาเฟี!B5 -> — | H43: =จับหัวใจเจ้าชายมาเฟี!B6 -> — | I43: =จับหัวใจเจ้าชายมาเฟี!B7 -> — | J43: =จับหัวใจเจ้าชายมาเฟี!B8 -> —
A44: 17 | B44: =รักนี้มีแต่เธอ!A1 -> รักนี้มีแต่เธอ | C44: โรแมนซ์ | D44: 35 | E44: รอลง | G44: =รักนี้มีแต่เธอ!B5 -> — | H44: =รักนี้มีแต่เธอ!B6 -> — | I44: =รักนี้มีแต่เธอ!B7 -> — | J44: =รักนี้มีแต่เธอ!B8 -> —
A45: 18 | B45: =พิษรักนางบำเรอ!A1 -> พิษรักนางบำเรอ | C45: ย้อนยุค | D45: 40 | E45: ผลิตแล้ว | G45: =พิษรักนางบำเรอ!B5 -> — | H45: =พิษรักนางบำเรอ!B6 -> — | I45: =พิษรักนางบำเรอ!B7 -> — | J45: =พิษรักนางบำเรอ!B8 -> —
A46: 19 | B46: =ลิขิตรักข้ามเวลา!A1 -> ลิขิตรักข้ามเวลา | C46: แฟนตาซี | D46: 45 | E46: กำลังผลิต | G46: =ลิขิตรักข้ามเวลา!B5 -> — | H46: =ลิขิตรักข้ามเวลา!B6 -> — | I46: =ลิขิตรักข้ามเวลา!B7 -> — | J46: =ลิขิตรักข้ามเวลา!B8 -> —
...

Sheet 📅 WEEKLY
A1: 📅 งานสัปดาห์นี้ — 10-16 ก.พ. 2026
A2: เปิดใหม่: จัน/พุธ/ศุกร์ (3 เรื่อง) | เรื่องเก่า: วันละ 1 ตอน
A4: ⭐ เปิดเรื่องใหม่ (จัน / พุธ / ศุกร์)
A5: วัน | B5: เรื่อง | C5: แพลตฟอร์ม | D5: ลงตอน | E5: กฎ | F5: เวลา | G5: ✅
A6: จันทร์ | B6: ดักรักเลขาสาว | C6: ธัญวลัย | D6: 1-5 | E6: Day1=5ตอน, Day2=5, แล้ววันละ1 | F6: 20:00
A7: พุธ | B7: คืนนั้นกับคนแปลกหน้า | C7: readAwrite | D7: 1-5 | E7: Day1=5ตอน, Day2=5, แล้ววันละ1 | F7: 21:00
A8: ศุกร์ | B8: ซ่อนรักไว้ในใจ | C8: ธัญวลัย | D8: 1-5 | E8: Day1=5ตอน, Day2=5, แล้ววันละ1 | F8: 20:00
A11: 📤 ลงประจำ วันละ 1 ตอน
A12: เรื่อง | B12: แพลตฟอร์ม | C12: จ | D12: อ | E12: พ | F12: พฤ | G12: ศ
A13: เมียลับท่านประธาน | B13: ธัญวลัย | C13: 36 | D13: 37 | E13: 38 | F13: 39 | G13: 40
A14: เมียลับท่านประธาน | B14: readAwrite | C14: 31 | D14: 32 | E14: 33 | F14: 34 | G14: 35
A15: เมียลับท่านประธาน | B15: Dek-D | C15: 23 | D15: 24 | E15: 25 | F15: 26 | G15: 27
A16: บังคับรักมาเฟียร้าย | B16: ธัญวลัย | C16: 41 | D16: 42 | E16: 43 | F16: 44 | G16: 45
A17: บังคับรักมาเฟียร้าย | B17: readAwrite | C17: 36 | D17: 37 | E17: 38 | F17: 39 | G17: 40
A18: บังคับรักมาเฟียร้าย | B18: Fictionlog | C18: 29 | D18: 30 | E18: 31 | F18: 32 | G18: 33
A19: หมอร้ายได้อีก | B19: ธัญวลัย | C19: 43 | D19: 44 | E19: 45 | F19: 46 | G19: 47
A20: หมอร้ายได้อีก | B20: readAwrite | C20: 39 | D20: 40 | E20: 41 | F20: 42 | G20: 43
A21: หมอร้ายได้อีก | B21: Dek-D | C21: 31 | D21: 32 | E21: 33 | F21: 34 | G21: 35
A22: หมอร้ายได้อีก | B22: Fictionlog | C22: 26 | D22: 27 | E22: 28 | F22: 29 | G22: 30
A23: ฮาเร็มท่านCEO | B23: ธัญวลัย | C23: 46 | D23: 47 | E23: 48 | F23: 49 | G23: 50
A24: ฮาเร็มท่านCEO | B24: readAwrite | C24: 41 | D24: 42 | E24: 43 | F24: 44 | G24: 45
... A31: กลับมารักฉันอีกครั้ง | B31: ธัญวลัย | C31: 13 | D31: 14 | E31: 15 | F31: 16 | G31: 17
A33: 📋 สรุป
A34: เรื่องเปิดใหม่: 3 เรื่อง (จัน/พุธ/ศุกร์)
A35: ลงประจำ: 19 สาย × วันละ 1 ตอน
A36: เวลา: ธัญวลัย 20:00 | readAwrite 21:00 | Dek-D 19:00 | Fictionlog 20:30

Sheet เมียลับท่านประธาน
A1: 🔥 เมียลับท่านประธาน
A2: แนว: CEO | ตอนทั้งหมด: 50 | 💰Paywall: ตอน 20 | สถานะ: กำลังลง
E3: ลงแล้ว | G3: ยังไม่ลง | I3: 💰 Paywall
A4: แพลตฟอร์ม | B4: ลงถึง ตอน | C4: % | D4: 1 | H4: 5 | M4: 10 | R4: 15 | W4: 20 | AB4: 25 | AG4: 30 | AL4: 35 | AQ4: 40 | AV4: 45 | BA4: 50
A5: ธัญวลัย | B5: 35 | C5: =B5/50 -> 0.7 | AM5: ▶
A6: readAwrite | B6: 30 | C6: =B6/50 -> 0.6 | AH6: ▶
A7: Dek-D | B7: 22 | C7: =B7/50 -> 0.44 | Z7: ▶
A8: Fictionlog | B8: — | C8: 0
A10: 📌 กฎการลง
A11: Day 1: ลง 5 ตอน → Day 2: ลง 5 ตอน → หลังจากนั้นวันละ 1
A12: 💰 Paywall ตอนที่ 20 | ถ้า <5k views ที่ตอน 25 → หยุด

Sheet บังคับรักมาเฟียร้าย
A1: 🔥 บังคับรักมาเฟียร้าย
A2: แนว: มาเฟีย | ตอนทั้งหมด: 45 | 💰Paywall: ตอน 20 | สถานะ: กำลังลง
E3: ลงแล้ว | G3: ยังไม่ลง | I3: 💰 Paywall
A4: แพลตฟอร์ม | B4: ลงถึง ตอน | C4: % | D4: 1 | H4: 5 | M4: 10 | R4: 15 | W4: 20 | AB4: 25 | AG4: 30 | AL4: 35 | AQ4: 40 | AV4: 45
A5: ธัญวลัย | B5: 40 | C5: =B5/45 -> 0.88888889 | AR5: ▶
A6: readAwrite | B6: 35 | C6: =B6/45 -> 0.77777778 | AM6: ▶
A7: Dek-D | B7: — | C7: 0
A8: Fictionlog | B8: 28 | C8: =B8/45 -> 0.62222222 | AF8: ▶
A10: 📌 กฎการลง
A11: Day 1: ลง 5 ตอน → Day 2: ลง 5 ตอน → หลังจากนั้นวันละ 1
A12: 💰 Paywall ตอนที่ 20 | ถ้า <5k views ที่ตอน 25 → หยุด

Sheet พลาดท้องกับเจ้านาย
A1: พลาดท้องกับเจ้านาย
A2: แนว: ออฟฟิศ | ตอนทั้งหมด: 40 | 💰Paywall: ตอน 20 | สถานะ: กำลังลง
E3: ลงแล้ว | G3: ยังไม่ลง | I3: 💰 Paywall
A4: แพลตฟอร์ม | B4: ลงถึง ตอน | C4: % | D4: 1 | H4: 5 | M4: 10 | R4: 15 | W4: 20 | AB4: 25 | AG4: 30 | AL4: 35 | AQ4: 40
A5: ธัญวลัย | B5: 18 | C5: =B5/40 -> 0.45 | V5: ▶
A6: readAwrite | B6: 14 | C6: =B6/40 -> 0.35 | R6: ▶
A7: Dek-D | B7: — | C7: 0
A8: Fictionlog | B8: — | C8: 0
A10: 📌 กฎการลง
A11: Day 1: ลง 5 ตอน → Day 2: ลง 5 ตอน → หลังจากนั้นวันละ 1
A12: 💰 Paywall ตอนที่ 20 | ถ้า <5k views ที่ตอน 25 → หยุด

Sheet หมอร้ายได้อีก
A1: 🔥 หมอร้ายได้อีก
A2: แนว: หมอ | ตอนทั้งหมด: 50 | 💰Paywall: ตอน 20 | สถานะ: กำลังลง
E3: ลงแล้ว | G3: ยังไม่ลง | I3: 💰 Paywall
A4: แพลตฟอร์ม | B4: ลงถึง ตอน | C4: % | D4: 1 | H4: 5 | M4: 10 | R4: 15 | W4: 20 | AB4: 25 | AG4: 30 | AL4: 35 | AQ4: 40 | AV4: 45 | BA4: 50
A5: ธัญวลัย | B5: 42 | C5: =B5/50 -> 0.84 | AT5: ▶
A6: readAwrite | B6: 38 | C6: =B6/50 -> 0.76 | AP6: ▶
A7: Dek-D | B7: 30 | C7: =B7/50 -> 0.6 | AH7: ▶
A8: Fictionlog | B8: 25 | C8: =B8/50 -> 0.5 | AC8: ▶
A10: 📌 กฎการลง
A11: Day 1: ลง 5 ตอน → Day 2: ลง 5 ตอน → หลังจากนั้นวันละ 1
A12: 💰 Paywall ตอนที่ 20 | ถ้า <5k views ที่ตอน 25 → หยุด

Sheet ฮาเร็มท่านCEO
A1: 🔥 ฮาเร็มท่านCEO
A2: แนว: ฮาเร็ม | ตอนทั้งหมด: 50 | 💰Paywall: ตอน 25 | สถานะ: กำลังลง
E3: ลงแล้ว | G3: ยังไม่ลง | I3: 💰 Paywall
A4: แพลตฟอร์ม | B4: ลงถึง ตอน | C4: % | D4: 1 | H4: 5 | M4: 10 | R4: 15 | W4: 20 | AB4: 25 | AG4: 30 | AL4: 35 | AQ4: 40 | AV4: 45 | BA4: 50
A5: ธัญวลัย | B5: 45 | C5: =B5/50 -> 0.9 | AW5: ▶
A6: readAwrite | B6: 40 | C6: =B6/50 -> 0.8 | AR6: ▶
A7: Dek-D | B7: 32 | C7: =B7/50 -> 0.64 | AJ7: ▶
A8: Fictionlog | B8: 28 | C8: =B8/50 -> 0.56 | AF8: ▶
A10: 📌 กฎการลง
A11: Day 1: ลง 5 ตอน → Day 2: ลง 5 ตอน → หลังจากนั้นวันละ 1
A12: 💰 Paywall ตอนที่ 25 | ถ้า <5k views ที่ตอน 25 → หยุด

Sheet คุณชายร้ายกาจ
A1: คุณชายร้ายกาจ
A2: แนว: CEO | ตอนทั้งหมด: 45 | 💰Paywall: ตอน 20 | สถานะ: กำลังลง
E3: ลงแล้ว | G3: ยังไม่ลง | I3: 💰 Paywall
A4: แพลตฟอร์ม | B4: ลงถึง ตอน | C4: % | D4: 1 | H4: 5 | M4: 10 | R4: 15 | W4: 20 | AB4: 25 | AG4: 30 | AL4: 35 | AQ4: 40 | AV4: 45
A5: ธัญวลัย | B5: 20 | C5: =B5/45 -> 0.44444444 | X5: ▶
A6: readAwrite | B6: — | C6: 0
A7: Dek-D | B7: — | C7: 0
A8: Fictionlog | B8: — | C8: 0
A10: 📌 กฎการลง
A11: Day 1: ลง 5 ตอน → Day 2: ลง 5 ตอน → หลังจากนั้นวันละ 1
A12: 💰 Paywall ตอนที่ 20 | ถ้า <5k views ที่ตอน 25 → หยุด

Sheet จอมใจนายทหาร
A1: จอมใจนายทหาร
A2: แนว: ทหาร | ตอนทั้งหมด: 40 | 💰Paywall: ตอน 20 | สถานะ: กำลังลง
E3: ลงแล้ว | G3: ยังไม่ลง | I3: 💰 Paywall
A4: แพลตฟอร์ม | B4: ลงถึง ตอน | C4: % | D4: 1 | H4: 5 | M4: 10 | R4: 15 | W4: 20 | AB4: 25 | AG4: 30 | AL4: 35 | AQ4: 40
A5: ธัญวลัย | B5: 15 | C5: =B5/40 -> 0.375 | S5: ▶
A6: readAwrite | B6: — | C6: 0
A7: Dek-D | B7: — | C7: 0
A8: Fictionlog | B8: — | C8: 0
A10: 📌 กฎการลง
A11: Day 1: ลง 5 ตอน → Day 2: ลง 5 ตอน → หลังจากนั้นวันละ 1
A12: 💰 Paywall ตอนที่ 20 | ถ้า <5k views ที่ตอน 25 → หยุด

Sheet กลับมารักฉันอีกครั้ง
A1: กลับมารักฉันอีกครั้ง
A2: แนว: แก้แค้น | ตอนทั้งหมด: 50 | 💰Paywall: ตอน 20 | สถานะ: กำลังลง
E3: ลงแล้ว | G3: ยังไม่ลง | I3: 💰 Paywall
A4: แพลตฟอร์ม | B4: ลงถึง ตอน | C4: % | D4: 1 | H4: 5 | M4: 10 | R4: 15 | W4: 20 | AB4: 25 | AG4: 30 | AL4: 35 | AQ4: 40 | AV4: 45 | BA4: 50
A5: ธัญวลัย | B5: 12 | C5: =B5/50 -> 0.24 | P5: ▶
A6: readAwrite | B6: — | C6: 0
A7: Dek-D | B7: — | C7: 0
A8: Fictionlog | B8: — | C8: 0
A10: 📌 กฎการลง
A11: Day 1: ลง 5 ตอน → Day 2: ลง 5 ตอน → หลังจากนั้นวันละ 1
A12: 💰 Paywall ตอนที่ 20 | ถ้า <5k views ที่ตอน 25 → หยุด

Sheet ดักรักเลขาสาว
A1: ดักรักเลขาสาว
A2: แนว: CEO | ตอนทั้งหมด: 40 | 💰Paywall: ตอน 20 | สถานะ: ผลิตแล้ว
E3: ลงแล้ว | G3: ยังไม่ลง | I3: 💰 Paywall
A4: แพลตฟอร์ม | B4: ลงถึง ตอน | C4: % | D4: 1 | H4: 5 | M4: 10 | R4: 15 | W4: 20 | AB4: 25 | AG4: 30 | AL4: 35 | AQ4: 40
A5: ธัญวลัย | B5: — | C5: 0
A6: readAwrite | B6: — | C6: 0
A7: Dek-D | B7: — | C7: 0
A8: Fictionlog | B8: — | C8: 0
A10: 📌 กฎการลง
A11: Day 1: ลง 5 ตอน → Day 2: ลง 5 ตอน → หลังจากนั้นวันละ 1
A12: 💰 Paywall ตอนที่ 20 | ถ้า <5k views ที่ตอน 25 → หยุด

Sheet คืนนั้นกับคนแปลกหน้า
A1: คืนนั้นกับคนแปลกหน้า
A2: แนว: ดราม่า | ตอนทั้งหมด: 45 | 💰Paywall: ตอน 25 | สถานะ: ผลิตแล้ว
E3: ลงแล้ว | G3: ยังไม่ลง | I3: 💰 Paywall
A4: แพลตฟอร์ม | B4: ลงถึง ตอน | C4: % | D4: 1 | H4: 5 | M4: 10 | R4: 15 | W4: 20 | AB4: 25 | AG4: 30 | AL4: 35 | AQ4: 40 | AV4: 45
A5: ธัญวลัย | B5: — | C5: 0
A6: readAwrite | B6: — | C6: 0
A7: Dek-D | B7: — | C7: 0
A8: Fictionlog | B8: — | C8: 0
A10: 📌 กฎการลง
A11: Day 1: ลง 5 ตอน → Day 2: ลง 5 ตอน → หลังจากนั้นวันละ 1
A12: 💰 Paywall ตอนที่ 25 | ถ้า <5k views ที่ตอน 25 → หยุด

Sheet ซ่อนรักไว้ในใจ
A1: ซ่อนรักไว้ในใจ
A2: แนว: โรแมนซ์ | ตอนทั้งหมด: 35 | 💰Paywall: ตอน 20 | สถานะ: ผลิตแล้ว
E3: ลงแล้ว | G3: ยังไม่ลง | I3: 💰 Paywall
A4: แพลตฟอร์ม | B4: ลงถึง ตอน | C4: % | D4: 1 | H4: 5 | M4: 10 | R4: 15 | W4: 20 | AB4: 25 | AG4: 30 | AL4: 35
A5: ธัญวลัย | B5: — | C5: 0
A6: readAwrite | B6: — | C6: 0
A7: Dek-D | B7: — | C7: 0
A8: Fictionlog | B8: — | C8: 0
A10: 📌 กฎการลง
A11: Day 1: ลง 5 ตอน → Day 2: ลง 5 ตอน → หลังจากนั้นวันละ 1
A12: 💰 Paywall ตอนที่ 20 | ถ้า <5k views ที่ตอน 25 → หยุด

Sheet สัญญารักร้อน
A1: สัญญารักร้อน
A2: แนว: สัญญา | ตอนทั้งหมด: 40 | 💰Paywall: ตอน 20 | สถานะ: กำลังผลิต
E3: ลงแล้ว | G3: ยังไม่ลง | I3: 💰 Paywall
A4: แพลตฟอร์ม | B4: ลงถึง ตอน | C4: % | D4: 1 | H4: 5 | M4: 10 | R4: 15 | W4: 20 | AB4: 25 | AG4: 30 | AL4: 35 | AQ4: 40
A5: ธัญวลัย | B5: — | C5: 0
A6: readAwrite | B6: — | C6: 0
A7: Dek-D | B7: — | C7: 0
A8: Fictionlog | B8: — | C8: 0
A10: 📌 กฎการลง
A11: Day 1: ลง 5 ตอน → Day 2: ลง 5 ตอน → หลังจากนั้นวันละ 1
A12: 💰 Paywall ตอนที่ 20 | ถ้า <5k views ที่ตอน 25 → หยุด

Sheet เกมรักอันตราย
A1: เกมรักอันตราย
A2: แนว: สืบสวน | ตอนทั้งหมด: 45 | 💰Paywall: ตอน 20 | สถานะ: กำลังผลิต
E3: ลงแล้ว | G3: ยังไม่ลง | I3: 💰 Paywall
A4: แพลตฟอร์ม | B4: ลงถึง ตอน | C4: % | D4: 1 | H4: 5 | M4: 10 | R4: 15 | W4: 20 | AB4: 25 | AG4: 30 | AL4: 35 | AQ4: 40 | AV4: 45
A5: ธัญวลัย | B5: — | C5: 0
A6: readAwrite | B6: — | C6: 0
A7: Dek-D | B7: — | C7: 0
A8: Fictionlog | B8: — | C8: 0
A10: 📌 กฎการลง
A11: Day 1: ลง 5 ตอน → Day 2: ลง 5 ตอน → หลังจากนั้นวันละ 1
A12: 💰 Paywall ตอนที่ 20 | ถ้า <5k views ที่ตอน 25 → หยุด

Sheet รักข้ามชนชั้น
A1: รักข้ามชนชั้น
A2: แนว: ดราม่า | ตอนทั้งหมด: 40 | 💰Paywall: ตอน 20 | สถานะ: ผลิตแล้ว
E3: ลงแล้ว | G3: ยังไม่ลง | I3: 💰 Paywall
A4: แพลตฟอร์ม | B4: ลงถึง ตอน | C4: % | D4: 1 | H4: 5 | M4: 10 | R4: 15 | W4: 20 | AB4: 25 | AG4: 30 | AL4: 35 | AQ4: 40
A5: ธัญวลัย | B5: — | C5: 0
A6: readAwrite | B6: — | C6: 0
A7: Dek-D | B7: — | C7: 0
A8: Fictionlog | B8: — | C8: 0
A10: 📌 กฎการลง
A11: Day 1: ลง 5 ตอน → Day 2: ลง 5 ตอน → หลังจากนั้นวันละ 1
A12: 💰 Paywall ตอนที่ 20 | ถ้า <5k views ที่ตอน 25 → หยุด

Sheet เสน่ห์ร้ายนายตำรวจ
A1: เสน่ห์ร้ายนายตำรวจ
A2: แนว: ตำรวจ | ตอนทั้งหมด: 45 | 💰Paywall: ตอน 20 | สถานะ: ผลิตแล้ว
E3: ลงแล้ว | G3: ยังไม่ลง | I3: 💰 Paywall
A4: แพลตฟอร์ม | B4: ลงถึง ตอน | C4: % | D4: 1 | H4: 5 | M4: 10 | R4: 15 | W4: 20 | AB4: 25 | AG4: 30 | AL4: 35 | AQ4: 40 | AV4: 45
A5: ธัญวลัย | B5: — | C5: 0
A6: readAwrite | B6: — | C6: 0
A7: Dek-D | B7: — | C7: 0
A8: Fictionlog | B8: — | C8: 0
A10: 📌 กฎการลง
A11: Day 1: ลง 5 ตอน → Day 2: ลง 5 ตอน → หลังจากนั้นวันละ 1
A12: 💰 Paywall ตอนที่ 20 | ถ้า <5k views ที่ตอน 25 → หยุด

Sheet จับหัวใจเจ้าชายมาเฟี
A1: จับหัวใจเจ้าชายมาเฟีย
A2: แนว: มาเฟีย | ตอนทั้งหมด: 50 | 💰Paywall: ตอน 25 | สถานะ: กำลังผลิต
E3: ลงแล้ว | G3: ยังไม่ลง | I3: 💰 Paywall
A4: แพลตฟอร์ม | B4: ลงถึง ตอน | C4: % | D4: 1 | H4: 5 | M4: 10 | R4: 15 | W4: 20 | AB4: 25 | AG4: 30 | AL4: 35 | AQ4: 40 | AV4: 45 | BA4: 50
A5: ธัญวลัย | B5: — | C5: 0
A6: readAwrite | B6: — | C6: 0
A7: Dek-D | B7: — | C7: 0
A8: Fictionlog | B8: — | C8: 0
A10: 📌 กฎการลง
A11: Day 1: ลง 5 ตอน → Day 2: ลง 5 ตอน → หลังจากนั้นวันละ 1
A12: 💰 Paywall ตอนที่ 25 | ถ้า <5k views ที่ตอน 25 → หยุด

Sheet รักนี้มีแต่เธอ
A1: รักนี้มีแต่เธอ
A2: แนว: โรแมนซ์ | ตอนทั้งหมด: 35 | 💰Paywall: ตอน 20 | สถานะ: รอลง
E3: ลงแล้ว | G3: ยังไม่ลง | I3: 💰 Paywall
A4: แพลตฟอร์ม | B4: ลงถึง ตอน | C4: % | D4: 1 | H4: 5 | M4: 10 | R4: 15 | W4: 20 | AB4: 25 | AG4: 30 | AL4: 35
A5: ธัญวลัย | B5: — | C5: 0
A6: readAwrite | B6: — | C6: 0
A7: Dek-D | B7: — | C7: 0
A8: Fictionlog | B8: — | C8: 0
A10: 📌 กฎการลง
A11: Day 1: ลง 5 ตอน → Day 2: ลง 5 ตอน → หลังจากนั้นวันละ 1
A12: 💰 Paywall ตอนที่ 20 | ถ้า <5k views ที่ตอน 25 → หยุด

Sheet พิษรักนางบำเรอ
A1: พิษรักนางบำเรอ
A2: แนว: ย้อนยุค | ตอนทั้งหมด: 40 | 💰Paywall: ตอน 20 | สถานะ: ผลิตแล้ว
E3: ลงแล้ว | G3: ยังไม่ลง | I3: 💰 Paywall
A4: แพลตฟอร์ม | B4: ลงถึง ตอน | C4: % | D4: 1 | H4: 5 | M4: 10 | R4: 15 | W4: 20 | AB4: 25 | AG4: 30 | AL4: 35 | AQ4: 40
A5: ธัญวลัย | B5: — | C5: 0
A6: readAwrite | B6: — | C6: 0
A7: Dek-D | B7: — | C7: 0
A8: Fictionlog | B8: — | C8: 0
A10: 📌 กฎการลง
A11: Day 1: ลง 5 ตอน → Day 2: ลง 5 ตอน → หลังจากนั้นวันละ 1
A12: 💰 Paywall ตอนที่ 20 | ถ้า <5k views ที่ตอน 25 → หยุด

Sheet ลิขิตรักข้ามเวลา
A1: ลิขิตรักข้ามเวลา
A2: แนว: แฟนตาซี | ตอนทั้งหมด: 45 | 💰Paywall: ตอน 25 | สถานะ: กำลังผลิต
E3: ลงแล้ว | G3: ยังไม่ลง | I3: 💰 Paywall
A4: แพลตฟอร์ม | B4: ลงถึง ตอน | C4: % | D4: 1 | H4: 5 | M4: 10 | R4: 15 | W4: 20 | AB4: 25 | AG4: 30 | AL4: 35 | AQ4: 40 | AV4: 45
A5: ธัญวลัย | B5: — | C5: 0
A6: readAwrite | B6: — | C6: 0
A7: Dek-D | B7: — | C7: 0
A8: Fictionlog | B8: — | C8: 0
A10: 📌 กฎการลง
A11: Day 1: ลง 5 ตอน → Day 2: ลง 5 ตอน → หลังจากนั้นวันละ 1
A12: 💰 Paywall ตอนที่ 25 | ถ้า <5k views ที่ตอน 25 → หยุด

Sheet เชลยรักทรราช
A1: เชลยรักทรราช
A2: แนว: ย้อนยุค | ตอนทั้งหมด: 40 | 💰Paywall: ตอน 20 | สถานะ: รอลง
E3: ลงแล้ว | G3: ยังไม่ลง | I3: 💰 Paywall
A4: แพลตฟอร์ม | B4: ลงถึง ตอน | C4: % | D4: 1 | H4: 5 | M4: 10 | R4: 15 | W4: 20 | AB4: 25 | AG4: 30 | AL4: 35 | AQ4: 40
A5: ธัญวลัย | B5: — | C5: 0
A6: readAwrite | B6: — | C6: 0
A7: Dek-D | B7: — | C7: 0
A8: Fictionlog | B8: — | C8: 0
A10: 📌 กฎการลง
A11: Day 1: ลง 5 ตอน → Day 2: ลง 5 ตอน → หลังจากนั้นวันละ 1
A12: 💰 Paywall ตอนที่ 20 | ถ้า <5k views ที่ตอน 25 → หยุด

Sheet บ่วงรักสาวใช้
A1: บ่วงรักสาวใช้
A2: แนว: ดราม่า | ตอนทั้งหมด: 35 | 💰Paywall: ตอน 20 | สถานะ: รอลง
E3: ลงแล้ว | G3: ยังไม่ลง | I3: 💰 Paywall
A4: แพลตฟอร์ม | B4: ลงถึง ตอน | C4: % | D4: 1 | H4: 5 | M4: 10 | R4: 15 | W4: 20 | AB4: 25 | AG4: 30 | AL4: 35
A5: ธัญวลัย | B5: — | C5: 0
A6: readAwrite | B6: — | C6: 0
A7: Dek-D | B7: — | C7: 0
A8: Fictionlog | B8: — | C8: 0
A10: 📌 กฎการลง
A11: Day 1: ลง 5 ตอน → Day 2: ลง 5 ตอน → หลังจากนั้นวันละ 1
A12: 💰 Paywall ตอนที่ 20 | ถ้า <5k views ที่ตอน 25 → หยุด

Sheet ร้อนรักวัยดรุณ
A1: ร้อนรักวัยดรุณ
A2: แนว: วัยรุ่น | ตอนทั้งหมด: 30 | 💰Paywall: ตอน 20 | สถานะ: ผลิตแล้ว
E3: ลงแล้ว | G3: ยังไม่ลง | I3: 💰 Paywall
A4: แพลตฟอร์ม | B4: ลงถึง ตอน | C4: % | D4: 1 | H4: 5 | M4: 10 | R4: 15 | W4: 20 | AB4: 25 | AG4: 30
A5: ธัญวลัย | B5: — | C5: 0
A6: readAwrite | B6: — | C6: 0
A7: Dek-D | B7: — | C7: 0
A8: Fictionlog | B8: — | C8: 0
A10: 📌 กฎการลง
A11: Day 1: ลง 5 ตอน → Day 2: ลง 5 ตอน → หลังจากนั้นวันละ 1
A12: 💰 Paywall ตอนที่ 20 | ถ้า <5k views ที่ตอน 25 → หยุด

Sheet ตกหลุมรักนายจอมหยิ่ง
A1: ตกหลุมรักนายจอมหยิ่ง
A2: แนว: CEO | ตอนทั้งหมด: 45 | 💰Paywall: ตอน 20 | สถานะ: กำลังผลิต
E3: ลงแล้ว | G3: ยังไม่ลง | I3: 💰 Paywall
A4: แพลตฟอร์ม | B4: ลงถึง ตอน | C4: % | D4: 1 | H4: 5 | M4: 10 | R4: 15 | W4: 20 | AB4: 25 | AG4: 30 | AL4: 35 | AQ4: 40 | AV4: 45
A5: ธัญวลัย | B5: — | C5: 0
A6: readAwrite | B6: — | C6: 0
A7: Dek-D | B7: — | C7: 0
A8: Fictionlog | B8: — | C8: 0
A10: 📌 กฎการลง
A11: Day 1: ลง 5 ตอน → Day 2: ลง 5 ตอน → หลังจากนั้นวันละ 1
A12: 💰 Paywall ตอนที่ 20 | ถ้า <5k views ที่ตอน 25 → หยุด

Sheet ทาสรักจอมโหด
A1: ทาสรักจอมโหด
A2: แนว: BDSM | ตอนทั้งหมด: 35 | 💰Paywall: ตอน 20 | สถานะ: ลงครบแล้ว
E3: ลงแล้ว | G3: ยังไม่ลง | I3: 💰 Paywall
A4: แพลตฟอร์ม | B4: ลงถึง ตอน | C4: % | D4: 1 | H4: 5 | M4: 10 | R4: 15 | W4: 20 | AB4: 25 | AG4: 30 | AL4: 35
A5: ธัญวลัย | B5: 35 | C5: =B5/35 -> 1
A6: readAwrite | B6: 35 | C6: =B6/35 -> 1
A7: Dek-D | B7: — | C7: 0
A8: Fictionlog | B8: — | C8: 0
A10: 📌 กฎการลง
A11: Day 1: ลง 5 ตอน → Day 2: ลง 5 ตอน → หลังจากนั้นวันละ 1
A12: 💰 Paywall ตอนที่ 20 | ถ้า <5k views ที่ตอน 25 → หยุด

Sheet แม่บ้านตัวร้าย
A1: แม่บ้านตัวร้าย
A2: แนว: ดราม่า | ตอนทั้งหมด: 40 | 💰Paywall: ตอน 20 | สถานะ: หยุดลง
E3: ลงแล้ว | G3: ยังไม่ลง | I3: 💰 Paywall
A4: แพลตฟอร์ม | B4: ลงถึง ตอน | C4: % | D4: 1 | H4: 5 | M4: 10 | R4: 15 | W4: 20 | AB4: 25 | AG4: 30 | AL4: 35 | AQ4: 40
A5: ธัญวลัย | B5: 18 | C5: =B5/40 -> 0.45 | V5: ▶
A6: readAwrite | B6: 14 | C6: =B6/40 -> 0.35 | R6: ▶
A7: Dek-D | B7: — | C7: 0
A8: Fictionlog | B8: — | C8: 0
A10: 📌 กฎการลง
A11: Day 1: ลง 5 ตอน → Day 2: ลง 5 ตอน → หลังจากนั้นวันละ 1
A12: 💰 Paywall ตอนที่ 20 | ถ้า <5k views ที่ตอน 25 → หยุด

Sheet สะดุดรักยัยจอมแก่น
A1: สะดุดรักยัยจอมแก่น
A2: แนว: โรแมนซ์ | ตอนทั้งหมด: 40 | 💰Paywall: ตอน 20 | สถานะ: ผลิตแล้ว
E3: ลงแล้ว | G3: ยังไม่ลง | I3: 💰 Paywall
A4: แพลตฟอร์ม | B4: ลงถึง ตอน | C4: % | D4: 1 | H4: 5 | M4: 10 | R4: 15 | W4: 20 | AB4: 25 | AG4: 30 | AL4: 35 | AQ4: 40
A5: ธัญวลัย | B5: — | C5: 0
A6: readAwrite | B6: — | C6: 0
A7: Dek-D | B7: — | C7: 0
A8: Fictionlog | B8: — | C8: 0
A10: 📌 กฎการลง
A11: Day 1: ลง 5 ตอน → Day 2: ลง 5 ตอน → หลังจากนั้นวันละ 1
A12: 💰 Paywall ตอนที่ 20 | ถ้า <5k views ที่ตอน 25 → หยุด

Sheet เพลิงรักนักบินหนุ่ม
A1: เพลิงรักนักบินหนุ่ม
A2: แนว: โรแมนซ์ | ตอนทั้งหมด: 35 | 💰Paywall: ตอน 20 | สถานะ: ผลิตแล้ว
E3: ลงแล้ว | G3: ยังไม่ลง | I3: 💰 Paywall
A4: แพลตฟอร์ม | B4: ลงถึง ตอน | C4: % | D4: 1 | H4: 5 | M4: 10 | R4: 15 | W4: 20 | AB4: 25 | AG4: 30 | AL4: 35
A5: ธัญวลัย | B5: — | C5: 0
A6: readAwrite | B6: — | C6: 0
A7: Dek-D | B7: — | C7: 0
A8: Fictionlog | B8: — | C8: 0
A10: 📌 กฎการลง
A11: Day 1: ลง 5 ตอน → Day 2: ลง 5 ตอน → หลังจากนั้นวันละ 1
A12: 💰 Paywall ตอนที่ 20 | ถ้า <5k views ที่ตอน 25 → หยุด

Sheet รักพิษสวาท
A1: รักพิษสวาท
A2: แนว: ดราม่า | ตอนทั้งหมด: 45 | 💰Paywall: ตอน 20 | สถานะ: กำลังผลิต
E3: ลงแล้ว | G3: ยังไม่ลง | I3: 💰 Paywall
A4: แพลตฟอร์ม | B4: ลงถึง ตอน | C4: % | D4: 1 | H4: 5 | M4: 10 | R4: 15 | W4: 20 | AB4: 25 | AG4: 30 | AL4: 35 | AQ4: 40 | AV4: 45
A5: ธัญวลัย | B5: — | C5: 0
A6: readAwrite | B6: — | C6: 0
A7: Dek-D | B7: — | C7: 0
A8: Fictionlog | B8: — | C8: 0
A10: 📌 กฎการลง
A11: Day 1: ลง 5 ตอน → Day 2: ลง 5 ตอน → หลังจากนั้นวันละ 1
A12: 💰 Paywall ตอนที่ 20 | ถ้า <5k views ที่ตอน 25 → หยุด

Sheet หัวใจทศกัณฐ์
A1: หัวใจทศกัณฐ์
A2: แนว: แฟนตาซี | ตอนทั้งหมด: 50 | 💰Paywall: ตอน 25 | สถานะ: กำลังผลิต
E3: ลงแล้ว | G3: ยังไม่ลง | I3: 💰 Paywall
A4: แพลตฟอร์ม | B4: ลงถึง ตอน | C4: % | D4: 1 | H4: 5 | M4: 10 | R4: 15 | W4: 20 | AB4: 25 | AG4: 30 | AL4: 35 | AQ4: 40 | AV4: 45 | BA4: 50
A5: ธัญวลัย | B5: — | C5: 0
A6: readAwrite | B6: — | C6: 0
A7: Dek-D | B7: — | C7: 0
A8: Fictionlog | B8: — | C8: 0
A10: 📌 กฎการลง
A11: Day 1: ลง 5 ตอน → Day 2: ลง 5 ตอน → หลังจากนั้นวันละ 1
A12: 💰 Paywall ตอนที่ 25 | ถ้า <5k views ที่ตอน 25 → หยุด

Sheet ขังรักไว้ในอ้อมแขน
A1: ขังรักไว้ในอ้อมแขน
A2: แนว: มาเฟีย | ตอนทั้งหมด: 40 | 💰Paywall: ตอน 20 | สถานะ: รอลง
E3: ลงแล้ว | G3: ยังไม่ลง | I3: 💰 Paywall
A4: แพลตฟอร์ม | B4: ลงถึง ตอน | C4: % | D4: 1 | H4: 5 | M4: 10 | R4: 15 | W4: 20 | AB4: 25 | AG4: 30 | AL4: 35 | AQ4: 40
A5: ธัญวลัย | B5: — | C5: 0
A6: readAwrite | B6: — | C6: 0
A7: Dek-D | B7: — | C7: 0
A8: Fictionlog | B8: — | C8: 0
A10: 📌 กฎการลง
A11: Day 1: ลง 5 ตอน → Day 2: ลง 5 ตอน → หลังจากนั้นวันละ 1
A12: 💰 Paywall ตอนที่ 20 | ถ้า <5k views ที่ตอน 25 → หยุด

Sheet ว่าที่เมียเจ้าพ่อ
A1: ว่าที่เมียเจ้าพ่อ
A2: แนว: มาเฟีย | ตอนทั้งหมด: 45 | 💰Paywall: ตอน 20 | สถานะ: ผลิตแล้ว
E3: ลงแล้ว | G3: ยังไม่ลง | I3: 💰 Paywall
A4: แพลตฟอร์ม | B4: ลงถึง ตอน | C4: % | D4: 1 | H4: 5 | M4: 10 | R4: 15 | W4: 20 | AB4: 25 | AG4: 30 | AL4: 35 | AQ4: 40 | AV4: 45
A5: ธัญวลัย | B5: — | C5: 0
A6: readAwrite | B6: — | C6: 0
A7: Dek-D | B7: — | C7: 0
A8: Fictionlog | B8: — | C8: 0
A10: 📌 กฎการลง
A11: Day 1: ลง 5 ตอน → Day 2: ลง 5 ตอน → หลังจากนั้นวันละ 1
A12: 💰 Paywall ตอนที่ 20 | ถ้า <5k views ที่ตอน 25 → หยุด

Sheet สลับชีวิตรัก
A1: สลับชีวิตรัก
A2: แนว: แฟนตาซี | ตอนทั้งหมด: 40 | 💰Paywall: ตอน 25 | สถานะ: ผลิตแล้ว
E3: ลงแล้ว | G3: ยังไม่ลง | I3: 💰 Paywall
A4: แพลตฟอร์ม | B4: ลงถึง ตอน | C4: % | D4: 1 | H4: 5 | M4: 10 | R4: 15 | W4: 20 | AB4: 25 | AG4: 30 | AL4: 35 | AQ4: 40
A5: ธัญวลัย | B5: — | C5: 0
A6: readAwrite | B6: — | C6: 0
A7: Dek-D | B7: — | C7: 0
A8: Fictionlog | B8: — | C8: 0
A10: 📌 กฎการลง
A11: Day 1: ลง 5 ตอน → Day 2: ลง 5 ตอน → หลังจากนั้นวันละ 1
A12: 💰 Paywall ตอนที่ 25 | ถ้า <5k views ที่ตอน 25 → หยุด

Sheet รักต้องห้ามนายหัว
A1: รักต้องห้ามนายหัว
A2: แนว: CEO | ตอนทั้งหมด: 45 | 💰Paywall: ตอน 20 | สถานะ: กำลังผลิต
E3: ลงแล้ว | G3: ยังไม่ลง | I3: 💰 Paywall
A4: แพลตฟอร์ม | B4: ลงถึง ตอน | C4: % | D4: 1 | H4: 5 | M4: 10 | R4: 15 | W4: 20 | AB4: 25 | AG4: 30 | AL4: 35 | AQ4: 40 | AV4: 45
A5: ธัญวลัย | B5: — | C5: 0
A6: readAwrite | B6: — | C6: 0
A7: Dek-D | B7: — | C7: 0
A8: Fictionlog | B8: — | C8: 0
A10: 📌 กฎการลง
A11: Day 1: ลง 5 ตอน → Day 2: ลง 5 ตอน → หลังจากนั้นวันละ 1
A12: 💰 Paywall ตอนที่ 20 | ถ้า <5k views ที่ตอน 25 → หยุด

Sheet บาปรักลวงใจ
A1: บาปรักลวงใจ
A2: แนว: ดราม่า | ตอนทั้งหมด: 40 | 💰Paywall: ตอน 20 | สถานะ: รอลง
E3: ลงแล้ว | G3: ยังไม่ลง | I3: 💰 Paywall
A4: แพลตฟอร์ม | B4: ลงถึง ตอน | C4: % | D4: 1 | H4: 5 | M4: 10 | R4: 15 | W4: 20 | AB4: 25 | AG4: 30 | AL4: 35 | AQ4: 40
A5: ธัญวลัย | B5: — | C5: 0
A6: readAwrite | B6: — | C6: 0
A7: Dek-D | B7: — | C7: 0
A8: Fictionlog | B8: — | C8: 0
A10: 📌 กฎการลง
A11: Day 1: ลง 5 ตอน → Day 2: ลง 5 ตอน → หลังจากนั้นวันละ 1
A12: 💰 Paywall ตอนที่ 20 | ถ้า <5k views ที่ตอน 25 → หยุด

Sheet จับจองนางในฝัน
A1: จับจองนางในฝัน
A2: แนว: โรแมนซ์ | ตอนทั้งหมด: 35 | 💰Paywall: ตอน 20 | สถานะ: ผลิตแล้ว
E3: ลงแล้ว | G3: ยังไม่ลง | I3: 💰 Paywall
A4: แพลตฟอร์ม | B4: ลงถึง ตอน | C4: % | D4: 1 | H4: 5 | M4: 10 | R4: 15 | W4: 20 | AB4: 25 | AG4: 30 | AL4: 35
A5: ธัญวลัย | B5: — | C5: 0
A6: readAwrite | B6: — | C6: 0
A7: Dek-D | B7: — | C7: 0
A8: Fictionlog | B8: — | C8: 0
A10: 📌 กฎการลง
A11: Day 1: ลง 5 ตอน → Day 2: ลง 5 ตอน → หลังจากนั้นวันละ 1
A12: 💰 Paywall ตอนที่ 20 | ถ้า <5k views ที่ตอน 25 → หยุด

Sheet เล่ห์รักวังวน
A1: เล่ห์รักวังวน
A2: แนว: ดราม่า | ตอนทั้งหมด: 40 | 💰Paywall: ตอน 20 | สถานะ: กำลังผลิต
E3: ลงแล้ว | G3: ยังไม่ลง | I3: 💰 Paywall
A4: แพลตฟอร์ม | B4: ลงถึง ตอน | C4: % | D4: 1 | H4: 5 | M4: 10 | R4: 15 | W4: 20 | AB4: 25 | AG4: 30 | AL4: 35 | AQ4: 40
A5: ธัญวลัย | B5: — | C5: 0
A6: readAwrite | B6: — | C6: 0
A7: Dek-D | B7: — | C7: 0
A8: Fictionlog | B8: — | C8: 0
A10: 📌 กฎการลง
A11: Day 1: ลง 5 ตอน → Day 2: ลง 5 ตอน → หลังจากนั้นวันละ 1
A12: 💰 Paywall ตอนที่ 20 | ถ้า <5k views ที่ตอน 25 → หยุด

Sheet หมาป่าหัวใจสิงห์
A1: หมาป่าหัวใจสิงห์
A2: แนว: แฟนตาซี | ตอนทั้งหมด: 50 | 💰Paywall: ตอน 25 | สถานะ: กำลังผลิต
E3: ลงแล้ว | G3: ยังไม่ลง | I3: 💰 Paywall
A4: แพลตฟอร์ม | B4: ลงถึง ตอน | C4: % | D4: 1 | H4: 5 | M4: 10 | R4: 15 | W4: 20 | AB4: 25 | AG4: 30 | AL4: 35 | AQ4: 40 | AV4: 45 | BA4: 50
A5: ธัญวลัย | B5: — | C5: 0
A6: readAwrite | B6: — | C6: 0
A7: Dek-D | B7: — | C7: 0
A8: Fictionlog | B8: — | C8: 0
A10: 📌 กฎการลง
A11: Day 1: ลง 5 ตอน → Day 2: ลง 5 ตอน → หลังจากนั้นวันละ 1
A12: 💰 Paywall ตอนที่ 25 | ถ้า <5k views ที่ตอน 25 → หยุด

Sheet รักนี้ไม่มีถอย
A1: รักนี้ไม่มีถอย
A2: แนว: โรแมนซ์ | ตอนทั้งหมด: 35 | 💰Paywall: ตอน 20 | สถานะ: ผลิตแล้ว
E3: ลงแล้ว | G3: ยังไม่ลง | I3: 💰 Paywall
A4: แพลตฟอร์ม | B4: ลงถึง ตอน | C4: % | D4: 1 | H4: 5 | M4: 10 | R4: 15 | W4: 20 | AB4: 25 | AG4: 30 | AL4: 35
A5: ธัญวลัย | B5: — | C5: 0
A6: readAwrite | B6: — | C6: 0
A7: Dek-D | B7: — | C7: 0
A8: Fictionlog | B8: — | C8: 0
A10: 📌 กฎการลง
A11: Day 1: ลง 5 ตอน → Day 2: ลง 5 ตอน → หลังจากนั้นวันละ 1
A12: 💰 Paywall ตอนที่ 20 | ถ้า <5k views ที่ตอน 25 → หยุด

Sheet ทัณฑ์รักสั่งสวรรค์
A1: ทัณฑ์รักสั่งสวรรค์
A2: แนว: ย้อนยุค | ตอนทั้งหมด: 40 | 💰Paywall: ตอน 20 | สถานะ: ผลิตแล้ว
E3: ลงแล้ว | G3: ยังไม่ลง | I3: 💰 Paywall
A4: แพลตฟอร์ม | B4: ลงถึง ตอน | C4: % | D4: 1 | H4: 5 | M4: 10 | R4: 15 | W4: 20 | AB4: 25 | AG4: 30 | AL4: 35 | AQ4: 40
A5: ธัญวลัย | B5: — | C5: 0
A6: readAwrite | B6: — | C6: 0
A7: Dek-D | B7: — | C7: 0
A8: Fictionlog | B8: — | C8: 0
A10: 📌 กฎการลง
A11: Day 1: ลง 5 ตอน → Day 2: ลง 5 ตอน → หลังจากนั้นวันละ 1
A12: 💰 Paywall ตอนที่ 20 | ถ้า <5k views ที่ตอน 25 → หยุด

Sheet พันธนาการรัก
A1: พันธนาการรัก
A2: แนว: BDSM | ตอนทั้งหมด: 35 | 💰Paywall: ตอน 20 | สถานะ: รอลง
E3: ลงแล้ว | G3: ยังไม่ลง | I3: 💰 Paywall
A4: แพลตฟอร์ม | B4: ลงถึง ตอน | C4: % | D4: 1 | H4: 5 | M4: 10 | R4: 15 | W4: 20 | AB4: 25 | AG4: 30 | AL4: 35
A5: ธัญวลัย | B5: — | C5: 0
A6: readAwrite | B6: — | C6: 0
A7: Dek-D | B7: — | C7: 0
A8: Fictionlog | B8: — | C8: 0
A10: 📌 กฎการลง
A11: Day 1: ลง 5 ตอน → Day 2: ลง 5 ตอน → หลังจากนั้นวันละ 1
A12: 💰 Paywall ตอนที่ 20 | ถ้า <5k views ที่ตอน 25 → หยุด

Sheet วิวาห์เดือด
A1: วิวาห์เดือด
A2: แนว: ดราม่า | ตอนทั้งหมด: 45 | 💰Paywall: ตอน 20 | สถานะ: ผลิตแล้ว
E3: ลงแล้ว | G3: ยังไม่ลง | I3: 💰 Paywall
A4: แพลตฟอร์ม | B4: ลงถึง ตอน | C4: % | D4: 1 | H4: 5 | M4: 10 | R4: 15 | W4: 20 | AB4: 25 | AG4: 30 | AL4: 35 | AQ4: 40 | AV4: 45
A5: ธัญวลัย | B5: — | C5: 0
A6: readAwrite | B6: — | C6: 0
A7: Dek-D | B7: — | C7: 0
A8: Fictionlog | B8: — | C8: 0
A10: 📌 กฎการลง
A11: Day 1: ลง 5 ตอน → Day 2: ลง 5 ตอน → หลังจากนั้นวันละ 1
A12: 💰 Paywall ตอนที่ 20 | ถ้า <5k views ที่ตอน 25 → หยุด

Sheet ข้ามเส้นรัก
A1: ข้ามเส้นรัก
A2: แนว: ออฟฟิศ | ตอนทั้งหมด: 40 | 💰Paywall: ตอน 20 | สถานะ: กำลังผลิต
E3: ลงแล้ว | G3: ยังไม่ลง | I3: 💰 Paywall
A4: แพลตฟอร์ม | B4: ลงถึง ตอน | C4: % | D4: 1 | H4: 5 | M4: 10 | R4: 15 | W4: 20 | AB4: 25 | AG4: 30 | AL4: 35 | AQ4: 40
A5: ธัญวลัย | B5: — | C5: 0
A6: readAwrite | B6: — | C6: 0
A7: Dek-D | B7: — | C7: 0
A8: Fictionlog | B8: — | C8: 0
A10: 📌 กฎการลง
A11: Day 1: ลง 5 ตอน → Day 2: ลง 5 ตอน → หลังจากนั้นวันละ 1
A12: 💰 Paywall ตอนที่ 20 | ถ้า <5k views ที่ตอน 25 → หยุด

Sheet ปักหมุดรักหัวใจ
A1: ปักหมุดรักหัวใจ
A2: แนว: โรแมนซ์ | ตอนทั้งหมด: 35 | 💰Paywall: ตอน 20 | สถานะ: ผลิตแล้ว
E3: ลงแล้ว | G3: ยังไม่ลง | I3: 💰 Paywall
A4: แพลตฟอร์ม | B4: ลงถึง ตอน | C4: % | D4: 1 | H4: 5 | M4: 10 | R4: 15 | W4: 20 | AB4: 25 | AG4: 30 | AL4: 35
A5: ธัญวลัย | B5: — | C5: 0
A6: readAwrite | B6: — | C6: 0
A7: Dek-D | B7: — | C7: 0
A8: Fictionlog | B8: — | C8: 0
A10: 📌 กฎการลง
A11: Day 1: ลง 5 ตอน → Day 2: ลง 5 ตอน → หลังจากนั้นวันละ 1
A12: 💰 Paywall ตอนที่ 20 | ถ้า <5k views ที่ตอน 25 → หยุด

Sheet เจ้าสาวซาตาน
A1: เจ้าสาวซาตาน
A2: แนว: มาเฟีย | ตอนทั้งหมด: 45 | 💰Paywall: ตอน 20 | สถานะ: รอลง
E3: ลงแล้ว | G3: ยังไม่ลง | I3: 💰 Paywall
A4: แพลตฟอร์ม | B4: ลงถึง ตอน | C4: % | D4: 1 | H4: 5 | M4: 10 | R4: 15 | W4: 20 | AB4: 25 | AG4: 30 | AL4: 35 | AQ4: 40 | AV4: 45
A5: ธัญวลัย | B5: — | C5: 0
A6: readAwrite | B6: — | C6: 0
A7: Dek-D | B7: — | C7: 0
A8: Fictionlog | B8: — | C8: 0
A10: 📌 กฎการลง
A11: Day 1: ลง 5 ตอน → Day 2: ลง 5 ตอน → หลังจากนั้นวันละ 1
A12: 💰 Paywall ตอนที่ 20 | ถ้า <5k views ที่ตอน 25 → หยุด

Sheet รักเกินห้ามใจ
A1: รักเกินห้ามใจ
A2: แนว: CEO | ตอนทั้งหมด: 40 | 💰Paywall: ตอน 20 | สถานะ: ผลิตแล้ว
E3: ลงแล้ว | G3: ยังไม่ลง | I3: 💰 Paywall
A4: แพลตฟอร์ม | B4: ลงถึง ตอน | C4: % | D4: 1 | H4: 5 | M4: 10 | R4: 15 | W4: 20 | AB4: 25 | AG4: 30 | AL4: 35 | AQ4: 40
A5: ธัญวลัย | B5: — | C5: 0
A6: readAwrite | B6: — | C6: 0
A7: Dek-D | B7: — | C7: 0
A8: Fictionlog | B8: — | C8: 0
A10: 📌 กฎการลง
A11: Day 1: ลง 5 ตอน → Day 2: ลง 5 ตอน → หลังจากนั้นวันละ 1
A12: 💰 Paywall ตอนที่ 20 | ถ้า <5k views ที่ตอน 25 → หยุด

Sheet คำสาปพญานาค
A1: คำสาปพญานาค
A2: แนว: แฟนตาซี | ตอนทั้งหมด: 50 | 💰Paywall: ตอน 25 | สถานะ: กำลังผลิต
E3: ลงแล้ว | G3: ยังไม่ลง | I3: 💰 Paywall
A4: แพลตฟอร์ม | B4: ลงถึง ตอน | C4: % | D4: 1 | H4: 5 | M4: 10 | R4: 15 | W4: 20 | AB4: 25 | AG4: 30 | AL4: 35 | AQ4: 40 | AV4: 45 | BA4: 50
A5: ธัญวลัย | B5: — | C5: 0
A6: readAwrite | B6: — | C6: 0
A7: Dek-D | B7: — | C7: 0
A8: Fictionlog | B8: — | C8: 0
A10: 📌 กฎการลง
A11: Day 1: ลง 5 ตอน → Day 2: ลง 5 ตอน → หลังจากนั้นวันละ 1
A12: 💰 Paywall ตอนที่ 25 | ถ้า <5k views ที่ตอน 25 → หยุด

Sheet สืบรักพิสูจน์ใจ
A1: สืบรักพิสูจน์ใจ
A2: แนว: สืบสวน | ตอนทั้งหมด: 40 | 💰Paywall: ตอน 20 | สถานะ: ผลิตแล้ว
E3: ลงแล้ว | G3: ยังไม่ลง | I3: 💰 Paywall
A4: แพลตฟอร์ม | B4: ลงถึง ตอน | C4: % | D4: 1 | H4: 5 | M4: 10 | R4: 15 | W4: 20 | AB4: 25 | AG4: 30 | AL4: 35 | AQ4: 40
A5: ธัญวลัย | B5: — | C5: 0
A6: readAwrite | B6: — | C6: 0
A7: Dek-D | B7: — | C7: 0
A8: Fictionlog | B8: — | C8: 0
A10: 📌 กฎการลง
A11: Day 1: ลง 5 ตอน → Day 2: ลง 5 ตอน → หลังจากนั้นวันละ 1
A12: 💰 Paywall ตอนที่ 20 | ถ้า <5k views ที่ตอน 25 → หยุด

Sheet เมียบังเอิญ
A1: เมียบังเอิญ
A2: แนว: CEO | ตอนทั้งหมด: 35 | 💰Paywall: ตอน 20 | สถานะ: รอลง
E3: ลงแล้ว | G3: ยังไม่ลง | I3: 💰 Paywall
A4: แพลตฟอร์ม | B4: ลงถึง ตอน | C4: % | D4: 1 | H4: 5 | M4: 10 | R4: 15 | W4: 20 | AB4: 25 | AG4: 30 | AL4: 35
A5: ธัญวลัย | B5: — | C5: 0
A6: readAwrite | B6: — | C6: 0
A7: Dek-D | B7: — | C7: 0
A8: Fictionlog | B8: — | C8: 0
A10: 📌 กฎการลง
A11: Day 1: ลง 5 ตอน → Day 2: ลง 5 ตอน → หลังจากนั้นวันละ 1
A12: 💰 Paywall ตอนที่ 20 | ถ้า <5k views ที่ตอน 25 → หยุด

Sheet จ้าวหัวใจจอมมาร
A1: จ้าวหัวใจจอมมาร
A2: แนว: แฟนตาซี | ตอนทั้งหมด: 50 | 💰Paywall: ตอน 25 | สถานะ: กำลังผลิต
E3: ลงแล้ว | G3: ยังไม่ลง | I3: 💰 Paywall
A4: แพลตฟอร์ม | B4: ลงถึง ตอน | C4: % | D4: 1 | H4: 5 | M4: 10 | R4: 15 | W4: 20 | AB4: 25 | AG4: 30 | AL4: 35 | AQ4: 40 | AV4: 45 | BA4: 50
A5: ธัญวลัย | B5: — | C5: 0
A6: readAwrite | B6: — | C6: 0
A7: Dek-D | B7: — | C7: 0
A8: Fictionlog | B8: — | C8: 0
A10: 📌 กฎการลง
A11: Day 1: ลง 5 ตอน → Day 2: ลง 5 ตอน → หลังจากนั้นวันละ 1
A12: 💰 Paywall ตอนที่ 25 | ถ้า <5k views ที่ตอน 25 → หยุด

Sheet รักสุดขอบฟ้า
A1: รักสุดขอบฟ้า
A2: แนว: โรแมนซ์ | ตอนทั้งหมด: 35 | 💰Paywall: ตอน 20 | สถานะ: ผลิตแล้ว
E3: ลงแล้ว | G3: ยังไม่ลง | I3: 💰 Paywall
A4: แพลตฟอร์ม | B4: ลงถึง ตอน | C4: % | D4: 1 | H4: 5 | M4: 10 | R4: 15 | W4: 20 | AB4: 25 | AG4: 30 | AL4: 35
A5: ธัญวลัย | B5: — | C5: 0
A6: readAwrite | B6: — | C6: 0
A7: Dek-D | B7: — | C7: 0
A8: Fictionlog | B8: — | C8: 0
A10: 📌 กฎการลง
A11: Day 1: ลง 5 ตอน → Day 2: ลง 5 ตอน → หลังจากนั้นวันละ 1
A12: 💰 Paywall ตอนที่ 20 | ถ้า <5k views ที่ตอน 25 → หยุด
